<?xml version="1.0" encoding="utf-8"?>
<!-- This URDF was automatically created by SolidWorks to URDF Exporter! Originally created by Stephen Brawner (brawner@gmail.com) 
     Commit Version: 1.6.0-4-g7f85cfe  Build Version: 1.6.7995.38578
     For more information, please see http://wiki.ros.org/sw_urdf_exporter -->
<robot
  name="kuka_kr4_description">
  <link
    name="base_link">
    <inertial>
      <origin
        xyz="-0.0368500181250583 0.000244396628154998 0.0902800424430135"
        rpy="0 0 0" />
      <mass
        value="6.63660865962053" />
      <inertia
        ixx="0.0302045851937558"
        ixy="0.000268177087976628"
        ixz="0.000387842158983764"
        iyy="0.0495672112934252"
        iyz="7.63241320530826E-05"
        izz="0.0477015697690725" />
    </inertial>
    <visual>
      <origin
        xyz="0 0 0"
        rpy="0 0 0" />
      <geometry>
        <mesh
          filename="package://kuka_kr4_description/meshes/base_link.STL" />
      </geometry>
      <material
        name="">
        <color
          rgba="0.8 0.8 0.8 1" />
      </material>
    </visual>
    <collision>
      <origin
        xyz="0 0 0"
        rpy="0 0 0" />
      <geometry>
        <mesh
          filename="package://kuka_kr4_description/meshes/base_link.STL" />
      </geometry>
    </collision>
  </link>
  <link
    name="l1">
    <inertial>
      <origin
        xyz="-0.00398448568004389 -0.000670963546183994 0.0931002781221804"
        rpy="0 0 0" />
      <mass
        value="3.49063221756745" />
      <inertia
        ixx="0.0291292834375306"
        ixy="1.52114599933444E-05"
        ixz="-7.35762659499248E-05"
        iyy="0.0187991881264951"
        iyz="0.000184294379323645"
        izz="0.0208252540178875" />
    </inertial>
    <visual>
      <origin
        xyz="0 0 0"
        rpy="0 0 0" />
      <geometry>
        <mesh
          filename="package://kuka_kr4_description/meshes/l1.STL" />
      </geometry>
      <material
        name="">
        <color
          rgba="0.8 0.8 0.8 1" />
      </material>
    </visual>
    <collision>
      <origin
        xyz="0 0 0"
        rpy="0 0 0" />
      <geometry>
        <mesh
          filename="package://kuka_kr4_description/meshes/l1.STL" />
      </geometry>
    </collision>
  </link>
  <joint
    name="j1"
    type="revolute">
    <origin
      xyz="0 0 0.167"
      rpy="0 0 0" />
    <parent
      link="base_link" />
    <child
      link="l1" />
    <axis
      xyz="0 0 -1" />
    <limit
      lower="-2.9671"
      upper="2.9671"
      effort="50"
      velocity="1.5708" />
  </joint>
  <link
    name="l2">
    <inertial>
      <origin
        xyz="-0.0106616717126077 0.00086836847408141 0.117714191465765"
        rpy="0 0 0" />
      <mass
        value="4.73302208355956" />
      <inertia
        ixx="0.0626532219978464"
        ixy="-2.19731763983951E-06"
        ixz="0.00101551284916567"
        iyy="0.0548126850176758"
        iyz="0.000574699493629899"
        izz="0.017086263280392" />
    </inertial>
    <visual>
      <origin
        xyz="0 0 0"
        rpy="0 0 0" />
      <geometry>
        <mesh
          filename="package://kuka_kr4_description/meshes/l2.STL" />
      </geometry>
      <material
        name="">
        <color
          rgba="0.8 0.8 0.8 1" />
      </material>
    </visual>
    <collision>
      <origin
        xyz="0 0 0"
        rpy="0 0 0" />
      <geometry>
        <mesh
          filename="package://kuka_kr4_description/meshes/l2.STL" />
      </geometry>
    </collision>
  </link>
  <joint
    name="j2"
    type="revolute">
    <origin
      xyz="0 0 0.163"
      rpy="0 0 0" />
    <parent
      link="l1" />
    <child
      link="l2" />
    <axis
      xyz="0 1 0" />
    <limit
      lower="-3.4034"
      upper="0.6981"
      effort="50"
      velocity="1.5708" />
  </joint>
  <link
    name="l3">
    <inertial>
      <origin
        xyz="0.0501649528884388 0.000845454520280513 0.0095148780365053"
        rpy="0 0 0" />
      <mass
        value="2.14150525350941" />
      <inertia
        ixx="0.00354767024315173"
        ixy="9.12927828408916E-05"
        ixz="-0.00108987339548338"
        iyy="0.0104347582957434"
        iyz="1.36839117862123E-05"
        izz="0.0100473954724049" />
    </inertial>
    <visual>
      <origin
        xyz="0 0 0"
        rpy="0 0 0" />
      <geometry>
        <mesh
          filename="package://kuka_kr4_description/meshes/l3.STL" />
      </geometry>
      <material
        name="">
        <color
          rgba="0.8 0.8 0.8 1" />
      </material>
    </visual>
    <collision>
      <origin
        xyz="0 0 0"
        rpy="0 0 0" />
      <geometry>
        <mesh
          filename="package://kuka_kr4_description/meshes/l3.STL" />
      </geometry>
    </collision>
  </link>
  <joint
    name="j3"
    type="revolute">
    <origin
      xyz="0 0 0.29"
      rpy="0 0 0" />
    <parent
      link="l2" />
    <child
      link="l3" />
    <axis
      xyz="0 1 0" />
    <limit
      lower="-2.0071"
      upper="2.618"
      effort="50"
      velocity="1.5708" />
  </joint>
  <link
    name="l4">
    <inertial>
      <origin
        xyz="0.0712982650650711 0.00253752478884897 0.00144424832320933"
        rpy="0 0 0" />
      <mass
        value="1.09604091906534" />
      <inertia
        ixx="0.00231551634598677"
        ixy="-0.00026275549522538"
        ixz="2.63780229322855E-05"
        iyy="0.00256904600774887"
        iyz="-4.4690361351986E-05"
        izz="0.00366373718717073" />
    </inertial>
    <visual>
      <origin
        xyz="0 0 0"
        rpy="0 0 0" />
      <geometry>
        <mesh
          filename="package://kuka_kr4_description/meshes/l4.STL" />
      </geometry>
      <material
        name="">
        <color
          rgba="0.8 0.8 0.8 1" />
      </material>
    </visual>
    <collision>
      <origin
        xyz="0 0 0"
        rpy="0 0 0" />
      <geometry>
        <mesh
          filename="package://kuka_kr4_description/meshes/l4.STL" />
      </geometry>
    </collision>
  </link>
  <joint
    name="j4"
    type="revolute">
    <origin
      xyz="0.16262 0 0.02"
      rpy="0 0 0" />
    <parent
      link="l3" />
    <child
      link="l4" />
    <axis
      xyz="-1 0 0" />
    <limit
      lower="-3.2289"
      upper="3.2289"
      effort="50"
      velocity="1.5708" />
  </joint>
  <link
    name="l5">
    <inertial>
      <origin
        xyz="0.0031430242316563 0.000478329633910871 -6.10578882631607E-06"
        rpy="0 0 0" />
      <mass
        value="0.544299272455749" />
      <inertia
        ixx="0.000475716381657173"
        ixy="-5.36620321626316E-06"
        ixz="-1.17376939202141E-07"
        iyy="0.000643393622745734"
        iyz="1.09478972938104E-07"
        izz="0.000685353197265738" />
    </inertial>
    <visual>
      <origin
        xyz="0 0 0"
        rpy="0 0 0" />
      <geometry>
        <mesh
          filename="package://kuka_kr4_description/meshes/l5.STL" />
      </geometry>
      <material
        name="">
        <color
          rgba="0.8 0.8 0.8 1" />
      </material>
    </visual>
    <collision>
      <origin
        xyz="0 0 0"
        rpy="0 0 0" />
      <geometry>
        <mesh
          filename="package://kuka_kr4_description/meshes/l5.STL" />
      </geometry>
    </collision>
  </link>
  <joint
    name="j5"
    type="revolute">
    <origin
      xyz="0.147378544382031 0 0"
      rpy="0 0 0" />
    <parent
      link="l4" />
    <child
      link="l5" />
    <axis
      xyz="0 1 0" />
    <limit
      lower="-2.0944"
      upper="2.0944"
      effort="50"
      velocity="1.5708" />
  </joint>
  <link
    name="l6">
    <inertial>
      <origin
        xyz="0.0145338104577156 -2.53745182932198E-06 -2.41488485164254E-06"
        rpy="0 0 0" />
      <mass
        value="0.0338899828627831" />
      <inertia
        ixx="9.48614875529737E-06"
        ixy="2.84660537031612E-11"
        ixz="2.33996435820421E-09"
        iyy="6.09021102051595E-06"
        iyz="-4.51660841807851E-13"
        izz="6.08920475486562E-06" />
    </inertial>
    <visual>
      <origin
        xyz="0 0 0"
        rpy="0 0 0" />
      <geometry>
        <mesh
          filename="package://kuka_kr4_description/meshes/l6.STL" />
      </geometry>
      <material
        name="">
        <color
          rgba="0.8 0.8 0.8 1" />
      </material>
    </visual>
    <collision>
      <origin
        xyz="0 0 0"
        rpy="0 0 0" />
      <geometry>
        <mesh
          filename="package://kuka_kr4_description/meshes/l6.STL" />
      </geometry>
    </collision>
  </link>
  <joint
    name="j6"
    type="revolute">
    <origin
      xyz="0.048 0 0"
      rpy="0 0 0" />
    <parent
      link="l5" />
    <child
      link="l6" />
    <axis
      xyz="-1 0 0" />
    <limit
      lower="-6.1086"
      upper="6.1086"
      effort="50"
      velocity="1.5708" />
  </joint>
  <link
    name="tool_1">
    <inertial>
      <origin
        xyz="-0.101995443575157 -1.89015094560156E-14 -0.0381024871134055"
        rpy="0 0 0" />
      <mass
        value="0.0123695159993075" />
      <inertia
        ixx="1.68961703917847E-06"
        ixy="-2.6313773311659E-21"
        ixz="-1.09720984915073E-07"
        iyy="1.87965935970787E-06"
        iyz="-1.62585249988229E-21"
        izz="1.8163119195314E-06" />
    </inertial>
    <visual>
      <origin
        xyz="0 0 0"
        rpy="0 0 0" />
      <geometry>
        <mesh
          filename="package://kuka_kr4_description/meshes/tool_1.STL" />
      </geometry>
      <material
        name="">
        <color
          rgba="0.752941176470588 0.752941176470588 0.752941176470588 1" />
      </material>
    </visual>
    <collision>
      <origin
        xyz="0 0 0"
        rpy="0 0 0" />
      <geometry>
        <mesh
          filename="package://kuka_kr4_description/meshes/tool_1.STL" />
      </geometry>
    </collision>
  </link>
  <joint
    name="fixed_joint_t1"
    type="fixed">
    <origin
      xyz="0.14418 0 -0.018"
      rpy="0 0.5236 0" />
    <parent
      link="l6" />
    <child
      link="tool_1" />
    <axis
      xyz="0 0 0" />
    <limit
      lower="0"
      upper="0"
      effort="0"
      velocity="0" />
  </joint>
  <link
    name="tool2">
    <inertial>
      <origin
        xyz="-0.0667654606407565 5.10949996958402E-09 -0.0194630751606795"
        rpy="0 0 0" />
      <mass
        value="0.00307725233002518" />
      <inertia
        ixx="5.91395321780285E-07"
        ixy="7.34553673139964E-14"
        ixz="-1.17280897671894E-06"
        iyy="3.08610812189225E-06"
        iyz="4.49023158810734E-14"
        izz="2.51079928601694E-06" />
    </inertial>
    <visual>
      <origin
        xyz="0 0 0"
        rpy="0 0 0" />
      <geometry>
        <mesh
          filename="package://kuka_kr4_description/meshes/tool2.STL" />
      </geometry>
      <material
        name="">
        <color
          rgba="0.752941176470588 0.752941176470588 0.752941176470588 1" />
      </material>
    </visual>
    <collision>
      <origin
        xyz="0 0 0"
        rpy="0 0 0" />
      <geometry>
        <mesh
          filename="package://kuka_kr4_description/meshes/tool2.STL" />
      </geometry>
    </collision>
  </link>
  <joint
    name="fixed_joint_t2"
    type="fixed">
    <origin
      xyz="0 0 0"
      rpy="0 0 0" />
    <parent
      link="tool_1" />
    <child
      link="tool2" />
    <axis
      xyz="0 0 0" />
  </joint>
</robot>