<?xml version="1.0" encoding="utf-8"?>
<!-- This URDF was automatically created by SolidWorks to URDF Exporter! Originally created by Stephen Brawner (brawner@gmail.com) 
     Commit Version: 1.6.0-4-g7f85cfe  Build Version: 1.6.7995.38578
     For more information, please see http://wiki.ros.org/sw_urdf_exporter -->
<robot
  name="kuka_kr4_description">
  <link
    name="base_link">
    <inertial>
      <origin
        xyz="-0.0368500181250583 0.000244396628154998 0.0902800424430135"
        rpy="0 0 0" />
      <mass
        value="6.63660865962053" />
      <inertia
        ixx="0.0302045851937558"
        ixy="0.000268177087976628"
        ixz="0.000387842158983764"
        iyy="0.0495672112934252"
        iyz="7.63241320530826E-05"
        izz="0.0477015697690725" />
    </inertial>
    <visual>
      <origin
        xyz="0 0 0"
        rpy="0 0 0" />
      <geometry>
        <mesh
          filename="package://kuka_kr4_description/meshes/base_link.STL" />
      </geometry>
      <material
        name="">
        <color
          rgba="0.8 0.8 0.8 1" />
      </material>
    </visual>
    <collision>
      <origin
        xyz="0 0 0"
        rpy="0 0 0" />
      <geometry>
        <mesh
          filename="package://kuka_kr4_description/meshes/base_link.STL" />
      </geometry>
    </collision>
  </link>
  <link
    name="l1">
    <inertial>
      <origin
        xyz="-0.0039844856810758 -0.00067096355112756 0.093100278125859"
        rpy="0 0 0" />
      <mass
        value="3.49063221731985" />
      <inertia
        ixx="0.0291292834354958"
        ixy="1.52114602604345E-05"
        ixz="-7.357626615347E-05"
        iyy="0.0187991881256857"
        iyz="0.000184294378345892"
        izz="0.0208252540165505" />
    </inertial>
    <visual>
      <origin
        xyz="0 0 0"
        rpy="0 0 0" />
      <geometry>
        <mesh
          filename="package://kuka_kr4_description/meshes/l1.STL" />
      </geometry>
      <material
        name="">
        <color
          rgba="0.8 0.8 0.8 1" />
      </material>
    </visual>
    <collision>
      <origin
        xyz="0 0 0"
        rpy="0 0 0" />
      <geometry>
        <mesh
          filename="package://kuka_kr4_description/meshes/l1.STL" />
      </geometry>
    </collision>
  </link>
  <joint
    name="j1"
    type="continuous">
    <origin
      xyz="0 0 0.167"
      rpy="0 0 0" />
    <parent
      link="base_link" />
    <child
      link="l1" />
    <axis
      xyz="0 0 -1" />
    <limit
      lower="-2.9671"
      upper="2.9671"
      effort="50"
      velocity="1.5708" />
  </joint>
  <link
    name="l2">
    <inertial>
      <origin
        xyz="-0.0106616717126078 0.000868368474081447 0.117714191465765"
        rpy="0 0 0" />
      <mass
        value="4.73302208355957" />
      <inertia
        ixx="0.0626532219978465"
        ixy="-2.19731763983443E-06"
        ixz="0.00101551284916568"
        iyy="0.0548126850176758"
        iyz="0.000574699493629885"
        izz="0.017086263280392" />
    </inertial>
    <visual>
      <origin
        xyz="0 0 0"
        rpy="0 0 0" />
      <geometry>
        <mesh
          filename="package://kuka_kr4_description/meshes/l2.STL" />
      </geometry>
      <material
        name="">
        <color
          rgba="0.8 0.8 0.8 1" />
      </material>
    </visual>
    <collision>
      <origin
        xyz="0 0 0"
        rpy="0 0 0" />
      <geometry>
        <mesh
          filename="package://kuka_kr4_description/meshes/l2.STL" />
      </geometry>
    </collision>
  </link>
  <joint
    name="j2"
    type="revolute">
    <origin
      xyz="0 0 0.163"
      rpy="0 0 0" />
    <parent
      link="l1" />
    <child
      link="l2" />
    <axis
      xyz="0 1 0" />
    <limit
      lower="-3.4034"
      upper="0.6981"
      effort="50"
      velocity="1.5708" />
  </joint>
  <link
    name="l3">
    <inertial>
      <origin
        xyz="0.0501649529813144 0.000845454485827052 0.00951487802711326"
        rpy="0 0 0" />
      <mass
        value="2.14150525089968" />
      <inertia
        ixx="0.00354767024077412"
        ixy="9.12927767751215E-05"
        ixz="-0.00108987339726161"
        iyy="0.0104347582806017"
        iyz="1.36839124165811E-05"
        izz="0.010047395455273" />
    </inertial>
    <visual>
      <origin
        xyz="0 0 0"
        rpy="0 0 0" />
      <geometry>
        <mesh
          filename="package://kuka_kr4_description/meshes/l3.STL" />
      </geometry>
      <material
        name="">
        <color
          rgba="0.8 0.8 0.8 1" />
      </material>
    </visual>
    <collision>
      <origin
        xyz="0 0 0"
        rpy="0 0 0" />
      <geometry>
        <mesh
          filename="package://kuka_kr4_description/meshes/l3.STL" />
      </geometry>
    </collision>
  </link>
  <joint
    name="j3"
    type="continuous">
    <origin
      xyz="0 0 0.29"
      rpy="0 0 0" />
    <parent
      link="l2" />
    <child
      link="l3" />
    <axis
      xyz="0 1 0" />
    <limit
      lower="-2.0071"
      upper="2.618"
      effort="50"
      velocity="1.5708" />
  </joint>
  <link
    name="l4">
    <inertial>
      <origin
        xyz="0.0712982652063201 0.00253752461554032 0.00144424815098632"
        rpy="0 0 0" />
      <mass
        value="1.09604091499795" />
      <inertia
        ixx="0.0023155163373801"
        ixy="-0.000262755501630189"
        ixz="2.63780182526531E-05"
        iyy="0.00256904600098361"
        iyz="-4.4690355965557E-05"
        izz="0.00366373717404835" />
    </inertial>
    <visual>
      <origin
        xyz="0 0 0"
        rpy="0 0 0" />
      <geometry>
        <mesh
          filename="package://kuka_kr4_description/meshes/l4.STL" />
      </geometry>
      <material
        name="">
        <color
          rgba="0.8 0.8 0.8 1" />
      </material>
    </visual>
    <collision>
      <origin
        xyz="0 0 0"
        rpy="0 0 0" />
      <geometry>
        <mesh
          filename="package://kuka_kr4_description/meshes/l4.STL" />
      </geometry>
    </collision>
  </link>
  <joint
    name="j4"
    type="continuous">
    <origin
      xyz="0.16262 0 0.02"
      rpy="0 0 0" />
    <parent
      link="l3" />
    <child
      link="l4" />
    <axis
      xyz="-1 0 0" />
    <limit
      lower="-3.2289"
      upper="3.2289"
      effort="50"
      velocity="1.5708" />
  </joint>
  <link
    name="l5">
    <inertial>
      <origin
        xyz="0.0031430242331742 0.000478329635039743 -6.10578971982356E-06"
        rpy="0 0 0" />
      <mass
        value="0.54429927248745" />
      <inertia
        ixx="0.000475716381676683"
        ixy="-5.36620323306413E-06"
        ixz="-1.17376925726157E-07"
        iyy="0.000643393622776597"
        iyz="1.09478982747951E-07"
        izz="0.000685353197300169" />
    </inertial>
    <visual>
      <origin
        xyz="0 0 0"
        rpy="0 0 0" />
      <geometry>
        <mesh
          filename="package://kuka_kr4_description/meshes/l5.STL" />
      </geometry>
      <material
        name="">
        <color
          rgba="0.8 0.8 0.8 1" />
      </material>
    </visual>
    <collision>
      <origin
        xyz="0 0 0"
        rpy="0 0 0" />
      <geometry>
        <mesh
          filename="package://kuka_kr4_description/meshes/l5.STL" />
      </geometry>
    </collision>
  </link>
  <joint
    name="j5"
    type="continuous">
    <origin
      xyz="0.14738 0 0"
      rpy="0 0 0" />
    <parent
      link="l4" />
    <child
      link="l5" />
    <axis
      xyz="0 1 0" />
    <limit
      lower="-2.0944"
      upper="2.0944"
      effort="50"
      velocity="1.5708" />
  </joint>
  <link
    name="l6">
    <inertial>
      <origin
        xyz="0.0145338104577156 -2.53745182932198E-06 -2.41488485164254E-06"
        rpy="0 0 0" />
      <mass
        value="0.0338899828627831" />
      <inertia
        ixx="9.48614875529737E-06"
        ixy="2.8466053703155E-11"
        ixz="2.33996435820428E-09"
        iyy="6.09021102051595E-06"
        iyz="-4.51660841811078E-13"
        izz="6.08920475486562E-06" />
    </inertial>
    <visual>
      <origin
        xyz="0 0 0"
        rpy="0 0 0" />
      <geometry>
        <mesh
          filename="package://kuka_kr4_description/meshes/l6.STL" />
      </geometry>
      <material
        name="">
        <color
          rgba="0.8 0.8 0.8 1" />
      </material>
    </visual>
    <collision>
      <origin
        xyz="0 0 0"
        rpy="0 0 0" />
      <geometry>
        <mesh
          filename="package://kuka_kr4_description/meshes/l6.STL" />
      </geometry>
    </collision>
  </link>
  <joint
    name="j6"
    type="continuous">
    <origin
      xyz="0.048 0 0"
      rpy="0 0 0" />
    <parent
      link="l5" />
    <child
      link="l6" />
    <axis
      xyz="-1 0 0" />
    <limit
      lower="-6.1086"
      upper="6.1086"
      effort="50"
      velocity="1.5708" />
  </joint>
  <link
    name="tool">
    <inertial>
      <origin
        xyz="-0.0343892072454799 -1.01788198433544E-09 -0.0949770469267289"
        rpy="0 0 0" />
      <mass
        value="0.0154467683293326" />
      <inertia
        ixx="7.3855729201555E-06"
        ixy="1.89785421825532E-13"
        ixz="-2.90069503274271E-06"
        iyy="8.88036487541175E-06"
        iyz="3.70123271669339E-13"
        izz="3.13714804016336E-06" />
    </inertial>
    <visual>
      <origin
        xyz="0 0 0"
        rpy="0 0 0" />
      <geometry>
        <mesh
          filename="package://kuka_kr4_description/meshes/tool.STL" />
      </geometry>
      <material
        name="">
        <color
          rgba="0.752941176470588 0.752941176470588 0.752941176470588 1" />
      </material>
    </visual>
    <collision>
      <origin
        xyz="0 0 0"
        rpy="0 0 0" />
      <geometry>
        <mesh
          filename="package://kuka_kr4_description/meshes/tool.STL" />
      </geometry>
    </collision>
  </link>
  <joint
    name="fixed_joint"
    type="fixed">
    <origin
      xyz="0.14418 0 -0.018"
      rpy="3.1416 -1.0472 0" />
    <parent
      link="l6" />
    <child
      link="tool" />
    <axis
      xyz="0 0 0" />
    <limit
      lower="0"
      upper="0"
      effort="0"
      velocity="0" />
  </joint>
</robot>